Workbook

Sheet Dashboard
B1: ◈ CINEMATOGRAPHER · MASTER DASHBOARD
B4: KPI OVERVIEW
B5: MONTHLY REVENUE | D5: PIPELINE VALUE | E5: BOOKED / MTH | F5: RESPONSE RATE | G5: HABITS TODAY | H5: LEVEL
B6: =Revenue!D14 | D6: =Pipeline!C3 | E6: =Pipeline!D3 | F6: =Pipeline!E3 | G6: =Habits!B6 | H6: =Habits!D4
B9: ACTIVE PIPELINE — TOP LEADS | F9: THIS WEEK · HABITS
B10: CLIENT | C10: SERVICE | D10: VALUE ($) | E10: STAGE | F10: NEXT ACTION
B11: Selam Films | C11: Commercial | D11: 3500 | E11: NEGOTIATING | F11: Craft Work | G11: ✓ ✓ ✓ ✓ ✓ — —
B12: KAYD Agency | C12: Brand Video | D12: 2200 | E12: PROPOSAL SENT | F12: Workout | G12: ✓ ✓ — ✓ ✓ ✓ —
B13: Henok Wedding | C13: Wedding Film | D13: 1800 | E13: BOOKED | F13: Client Outch | G13: ✓ — ✓ ✓ — ✓ —
B14: Nova Studios | C14: Music Video | D14: 2800 | E14: INTERESTED | F14: Read 20 min | G14: ✓ ✓ ✓ — ✓ ✓ ✓
B15: TeleBirhan | C15: Documentary | D15: 5000 | E15: CONTACTED | F15: Journaling | G15: — ✓ ✓ ✓ — — ✓
B17: DAILY SIGNAL
B18: =CHOOSE(WEEKDAY(TODAY()),"The frame is your truth — own it.","One great shot changes everything.","Light is language. Learn it deeply.","Your lens, your vision, your legacy.","Craft compounds. Show up daily.","The best directors were once broke filmmakers.","Motion is emotion — make them feel it.")

Sheet Pipeline
B1: ◈ CLIENT PIPELINE · OUTREACH TRACKER
B3: TOTAL PIPELINE | D3: BOOKED THIS MONTH | F3: ACTIVE LEADS | H3: RESPONSE RATE | J3: PROPOSALS OUT
B4: =SUMIF(E6:E205,"<>CLOSED LOST",C6:C205) | D4: =SUMIF(E6:E205,"BOOKED",C6:C205) | F4: =COUNTIF(E6:E205,"<>CLOSED LOST") | H4: =IFERROR(COUNTIF(E6:E205,"INTERESTED")/COUNTIF(E6:E205,"<>COLD"),"—") | J4: =COUNTIF(E6:E205,"PROPOSAL SENT")
B5: CLIENT NAME | C5: DEAL VALUE ($) | D5: SERVICE TYPE | E5: STAGE | F5: FIRST CONTACT | G5: LAST FOLLOW-UP | H5: NEXT ACTION | I5: DAYS SINCE CONTACT | J5: PRIORITY | K5: NOTES | L5: PROPOSAL? | M5: SIGNED?
B6: Selam Films | C6: 3500 | D6: Commercial | E6: NEGOTIATING | F6: 46185 | G6: 46187 | H6: Send revised proposal | I6: 1 | J6: 17.5 | L6: — | M6: —
B7: KAYD Agency | C7: 2200 | D7: Brand Video | E7: PROPOSAL SENT | F7: 46181 | G7: 46186 | H7: Follow up Tuesday | I7: 2 | J7: 8.8 | L7: YES | M7: —
B8: Henok Wedding | C8: 1800 | D8: Wedding Film | E8: BOOKED | F8: 46174 | G8: 46187 | H8: Pre-shoot call Friday | I8: 1 | J8: 10.8 | L8: YES | M8: —
B9: Nova Studios | C9: 2800 | D9: Music Video | E9: INTERESTED | F9: 46183 | G9: 46185 | H9: Schedule site visit | I9: 3 | J9: 8.4 | L9: — | M9: —
B10: TeleBirhan | C10: 5000 | D10: Documentary | E10: CONTACTED | F10: 46178 | G10: 46183 | H10: Send portfolio link | I10: 5 | J10: 10 | L10: — | M10: —
B11: Biruk Events | C11: 1500 | D11: Event Coverage | E11: COLD | F11: 46168 | G11: 46168 | H11: Initial outreach | I11: 20 | J11: 1.5 | L11: — | M11: —
B12: Liya Media | C12: 4200 | D12: Ad Campaign | E12: NEGOTIATING | F12: 46180 | G12: 46186 | H12: Confirm budget ceiling | I12: 2 | J12: 21 | L12: YES | M12: —
B13: Addis Photo | C13: 900 | D13: Product Shoot | E13: PROPOSAL SENT | F13: 46182 | G13: 46184 | H13: Chase response | I13: 4 | J13: 3.6 | L13: YES | M13: —

Sheet Pricing
B1: ◈ SERVICE RATE CARD · GOOD · BETTER · BEST
B4: TIER 1 · DAY RATE | C4: TIER 2 · PROJECT PKG | D4: TIER 3 · BRAND PARTNER
B6: Essential | C6: Standard | D6: Premium
B7: from $800 | C7: from $2,400 | D7: Custom Quote
B9: ✦ 1 camera operator ✦ Up to 8 hrs on location ✦ Basic color grade ✦ 1 final cut delivery ✦ Web-ready export | C9: ✦ 2-day shoot included ✦ 2 camera setups ✦ Full color grade + LUTs ✦ Sound design ✦ 2 revision rounds ✦ Drone add-on available | D9: ✦ Monthly retainer (4-8 shoot days) ✦ Dedicated edit suite ✦ Unlimited revisions ✦ Rush delivery included ✦ Usage rights: unlimited ✦ Creative direction included
B15: → Startups · Events · Small brands | C15: → Agencies · Music artists · SMEs | D15: → Corporates · Broadcast · Retainers
B17: ADD-ONS · À LA CARTE
B18: SERVICE | C18: PRICE | D18: NOTES
B19: Drone / Aerial | C19: $300 / day | D19: FAA-compliant operator
B20: Express Delivery | C20: +40% | D20: 72-hr turnaround
B21: Sound Design + Mix | C21: $250 / min | D21: Full audio post
B22: Extra Revision Round | C22: $150 each | D22: Beyond package limit
B23: BTS + Making-of | C23: $400 | D23: Additional camera
B24: Color Grade — Adv. | C24: $500 | D24: HDR + custom LUTs
B25: Usage: Broadcast | C25: +50% of fee | D25: TV / OTT platforms
B26: Usage: Unlimited | C26: +100% of fee | D26: All platforms, all time
B27: Subtitle / Caption | C27: $80 / video | D27: SRT file included
B28: Photography Add-on | C28: $350 / half-day | D28: Stills alongside video
B30: QUICK QUOTE CALCULATOR
B31: SELECT BASE TIER
B32: Tier 2 · Project Package | C32: 2400
B33: Drone / Aerial | C33: 300
B34: Express Delivery | C34: 0
B35: Color Grade (Adv.) | C35: 500
B37: ESTIMATED TOTAL | C37: =SUM(C32:C35)

Sheet Revenue
B1: ◈ REVENUE PLANNER · 12-MONTH TRACKER
B4: ANNUAL TARGET
B5: ANNUAL GOAL | D5: MONTHS LEFT | E5: MONTHLY NEEDED | F5: YTD COLLECTED | G5: PIPELINE NEED
B6: 36000 | D6: =6 | E6: =IFERROR((B5-SUM(D14:D25))/(12-MONTH(TODAY())),0) | F6: =SUM(D14:D25) | G6: =MAX(0,B5-SUM(D14:D25))
B12: MONTHLY BREAKDOWN
A13: MONTH | B13: BOOKED | C13: PROJECTED | D13: COLLECTED | E13: OUTSTANDING | F13: EXPENSES | G13: NET PROFIT | H13: MARGIN % | I13: PROGRESS
A14: January | B14: 2800 | C14: 3000 | D14: 2800 | E14: 0 | F14: 620 | G14: 2180 | H14: 0.779 | I14: ███████████████
A15: February | B15: 1800 | C15: 2000 | D15: 1800 | E15: 0 | F15: 540 | G15: 1260 | H15: 0.7 | I15: ███████████████
A16: March | B16: 3500 | C16: 3500 | D16: 3200 | E16: 300 | F16: 700 | G16: 2500 | H16: 0.781 | I16: █████████████░░
A17: April | B17: 2200 | C17: 2500 | D17: 2200 | E17: 0 | F17: 580 | G17: 1620 | H17: 0.736 | I17: ███████████████
A18: May | B18: 4200 | C18: 4000 | D18: 3800 | E18: 400 | F18: 820 | G18: 2980 | H18: 0.784 | I18: █████████████░░
A19: June | B19: 1500 | C19: 2000 | D19: 0 | E19: 0 | F19: 450 | G19: 0 | H19: 0 | I19: ░░░░░░░░░░░░░░░
A20: July | B20: 0 | C20: 2500 | D20: 0 | E20: 0 | F20: 0 | G20: 0 | H20: 0 | I20: ░░░░░░░░░░░░░░░
A21: August | B21: 0 | C21: 3000 | D21: 0 | E21: 0 | F21: 0 | G21: 0 | H21: 0 | I21: ░░░░░░░░░░░░░░░
A22: September | B22: 0 | C22: 2800 | D22: 0 | E22: 0 | F22: 0 | G22: 0 | H22: 0 | I22: ░░░░░░░░░░░░░░░
A23: October | B23: 0 | C23: 3200 | D23: 0 | E23: 0 | F23: 0 | G23: 0 | H23: 0 | I23: ░░░░░░░░░░░░░░░
A24: November | B24: 0 | C24: 3500 | D24: 0 | E24: 0 | F24: 0 | G24: 0 | H24: 0 | I24: ░░░░░░░░░░░░░░░
A25: December | B25: 0 | C25: 4000 | D25: 0 | E25: 0 | F25: 0 | G25: 0 | H25: 0 | I25: ░░░░░░░░░░░░░░░
A26: TOTALS | B26: =SUM(B14:B25) | C26: =SUM(C14:C25) | D26: =SUM(D14:D25) | E26: =SUM(E14:E25) | F26: =SUM(F14:F25) | G26: =SUM(G14:G25)

Sheet Habits
B1: ◈ LIFE GAMIFIER · CHARACTER DASHBOARD
B2: YOUR NAME | C2: [ YOUR NAME HERE ]
B3: CLASS | C3: Cinematographer · Visual Storyteller
B4: LEVEL | C4: =IFERROR(VLOOKUP(B6,Lookup!$D$2:$E$31,2,TRUE),"Apprentice") | D4: RANK: | G4: =IFERROR(VLOOKUP(B6,Lookup!$D$2:$E$31,3,FALSE),"Apprentice")
B5: TOTAL XP | C5: =IFERROR(SUM(L44:L73),0)
B6: XP BAR | C6: =REPT("█",MIN(20,INT(IFERROR(SUM(L44:L73),0)/500)))&REPT("░",MAX(0,20-MIN(20,INT(IFERROR(SUM(L44:L73),0)/500)))) | K6: / 10,000 XP
B7: STREAK | C7: =IFERROR(COUNTIF(M44:M73,TRUE),0) | D7: days with at least one habit completed
B9: 🎬 CRAFT
B10: HABIT | C10: XP | E10: M | F10: T | G10: W | H10: T | I10: F | J10: S | K10: S | L10: DONE | M10: XP ✓
B11: Review reference films | C11: 20 | E11: ✓ | F11: ✓ | G11: ✓ | H11: ✓ | I11: ✓ | J11: — | K11: — | L11: =COUNTIF(E11:K11,"✓") | M11: =IF(L11>0,C11,0)
B12: Practice shot composition | C12: 15 | E12: ✓ | F12: ✓ | G12: ✓ | H12: ✓ | I12: ✓ | J12: — | K12: — | L12: =COUNTIF(E12:K12,"✓") | M12: =IF(L12>0,C12,0)
B13: Edit personal project footage | C13: 25 | E13: — | F13: — | G13: — | H13: — | I13: — | J13: — | K13: — | L13: =COUNTIF(E13:K13,"✓") | M13: =IF(L13>0,C13,0)
B14: Study color grading technique | C14: 15 | E14: ✓ | F14: ✓ | G14: ✓ | H14: ✓ | I14: ✓ | J14: — | K14: — | L14: =COUNTIF(E14:K14,"✓") | M14: =IF(L14>0,C14,0)
B16: 💪 BODY
B17: HABIT | C17: XP | E17: M | F17: T | G17: W | H17: T | I17: F | J17: S | K17: S | L17: DONE | M17: XP ✓
B18: Workout / Movement (30 min+) | C18: 20 | E18: ✓ | F18: ✓ | G18: ✓ | H18: ✓ | I18: ✓ | J18: — | K18: — | L18: =COUNTIF(E18:K18,"✓") | M18: =IF(L18>0,C18,0)
B19: 8 hours of quality sleep | C19: 15 | E19: — | F19: — | G19: — | H19: — | I19: — | J19: — | K19: — | L19: =COUNTIF(E19:K19,"✓") | M19: =IF(L19>0,C19,0)
B20: No junk food today | C20: 10 | E20: ✓ | F20: ✓ | G20: ✓ | H20: ✓ | I20: ✓ | J20: — | K20: — | L20: =COUNTIF(E20:K20,"✓") | M20: =IF(L20>0,C20,0)
B21: Hydration goal (2L+) | C21: 10 | E21: ✓ | F21: ✓ | G21: ✓ | H21: ✓ | I21: ✓ | J21: — | K21: — | L21: =COUNTIF(E21:K21,"✓") | M21: =IF(L21>0,C21,0)
B23: 🧠 MIND
B24: HABIT | C24: XP | E24: M | F24: T | G24: W | H24: T | I24: F | J24: S | K24: S | L24: DONE | M24: XP ✓
B25: Morning pages / journaling | C25: 15 | E25: — | F25: — | G25: — | H25: — | I25: — | J25: — | K25: — | L25: =COUNTIF(E25:K25,"✓") | M25: =IF(L25>0,C25,0)
B26: Read 20 minutes | C26: 15 | E26: ✓ | F26: ✓ | G26: ✓ | H26: ✓ | I26: ✓ | J26: — | K26: — | L26: =COUNTIF(E26:K26,"✓") | M26: =IF(L26>0,C26,0)
B27: Meditation (10 min+) | C27: 10 | E27: ✓ | F27: ✓ | G27: ✓ | H27: ✓ | I27: ✓ | J27: — | K27: — | L27: =COUNTIF(E27:K27,"✓") | M27: =IF(L27>0,C27,0)
B28: Gratitude — 3 things | C28: 5 | E28: — | F28: — | G28: — | H28: — | I28: — | J28: — | K28: — | L28: =COUNTIF(E28:K28,"✓") | M28: =IF(L28>0,C28,0)
B30: 💼 BUSINESS
B31: HABIT | C31: XP | E31: M | F31: T | G31: W | H31: T | I31: F | J31: S | K31: S | L31: DONE | M31: XP ✓
B32: Outreach to 1+ potential client | C32: 25 | E32: ✓ | F32: ✓ | G32: ✓ | H32: ✓ | I32: ✓ | J32: — | K32: — | L32: =COUNTIF(E32:K32,"✓") | M32: =IF(L32>0,C32,0)
B33: Post content / BTS reel | C33: 20 | E33: ✓ | F33: ✓ | G33: ✓ | H33: ✓ | I33: ✓ | J33: — | K33: — | L33: =COUNTIF(E33:K33,"✓") | M33: =IF(L33>0,C33,0)
B34: Follow up on active proposals | C34: 20 | E34: — | F34: — | G34: — | H34: — | I34: — | J34: — | K34: — | L34: =COUNTIF(E34:K34,"✓") | M34: =IF(L34>0,C34,0)
B35: Review financials / pipeline | C35: 10 | E35: ✓ | F35: ✓ | G35: ✓ | H35: ✓ | I35: ✓ | J35: — | K35: — | L35: =COUNTIF(E35:K35,"✓") | M35: =IF(L35>0,C35,0)
B38: 30-DAY HABIT LOG
B39: DATE | C39: CRAFT | D39: BODY | E39: MIND | F39: BIZ | G39: TOTAL DONE | H39: XP TODAY | I39: DAILY BAR | J39: STREAK DAY?
B40: 46159 | D40: 0 | E40: 0 | F40: 0 | G40: 0 | H40: 0 | I40: ░░░░░░░░░░░░ | J40: FALSE
B41: 46160 | D41: 0 | E41: 0 | F41: 0 | G41: 0 | H41: 0 | I41: ░░░░░░░░░░░░ | J41: FALSE
B42: 46161 | D42: 0 | E42: 0 | F42: 0 | G42: 0 | H42: 0 | I42: ░░░░░░░░░░░░ | J42: FALSE
B43: 46162 | D43: 0 | E43: 0 | F43: 0 | G43: 0 | H43: 0 | I43: ░░░░░░░░░░░░ | J43: FALSE
B44: 46163 | D44: 0 | E44: 0 | F44: 0 | G44: 0 | H44: 0 | I44: ░░░░░░░░░░░░ | J44: FALSE
B45: 46164 | D45: 0 | E45: 0 | F45: 0 | G45: 0 | H45: 0 | I45: ░░░░░░░░░░░░ | J45: FALSE
B46: 46165 | D46: 0 | E46: 0 | F46: 0 | G46: 0 | H46: 0 | I46: ░░░░░░░░░░░░ | J46: FALSE
...

Sheet Lookup
A1: SERVICE_TYPES | D1: XP_MIN | E1: LEVEL | F1: RANK_TITLE
A2: Commercial | D2: 0 | E2: 1 | F2: Apprentice
A3: Wedding Film | D3: 200 | E3: 2 | F3: Apprentice II
A4: Music Video | D4: 400 | E4: 3 | F4: Apprentice III
A5: Documentary | D5: 600 | E5: 4 | F5: Journeyman
A6: Brand Video | D6: 900 | E6: 5 | F6: Journeyman II
A7: Event Coverage | D7: 1200 | E7: 6 | F7: Journeyman III
A8: Ad Campaign | D8: 1500 | E8: 7 | F8: Craftsman
A9: Product Shoot | D9: 1900 | E9: 8 | F9: Craftsman II
A10: Corporate Film | D10: 2300 | E10: 9 | F10: Craftsman III
A11: Personal Project | D11: 2700 | E11: 10 | F11: Artisan
D12: 3200 | E12: 11 | F12: Artisan II
D13: 3800 | E13: 12 | F13: Artisan III
D14: 4400 | E14: 13 | F14: Senior Artisan
D15: 5000 | E15: 14 | F15: Master
D16: 5800 | E16: 15 | F16: Master II
D17: 6700 | E17: 16 | F17: Master III
D18: 7700 | E18: 17 | F18: Grand Master
D19: 8800 | E19: 18 | F19: Grand Master II
D20: 9900 | E20: 19 | F20: Grand Master III
D21: 10000 | E21: 20 | F21: Legend
D22: 12000 | E22: 21 | F22: Legend II
D23: 14500 | E23: 22 | F23: Legend III
... D31: 50000 | E31: 30 | F31: LEGEND: CINEMATOGRAPHER
